OperationalError
sqlalchemy.exc.OperationalError: (sqlite3.OperationalError) no such column: wallet_deposit.deposit_method
[SQL: SELECT wallet_deposit.id AS wallet_deposit_id, wallet_deposit.user_id AS wallet_deposit_user_id, wallet_deposit.amount AS wallet_deposit_amount, wallet_deposit.deposit_method AS wallet_deposit_deposit_method, wallet_deposit.bank_name AS wallet_deposit_bank_name, wallet_deposit.account_number AS wallet_deposit_account_number, wallet_deposit.account_name AS wallet_deposit_account_name, wallet_deposit.payment_proof AS wallet_deposit_payment_proof, wallet_deposit.reference_number AS wallet_deposit_reference_number, wallet_deposit.status AS wallet_deposit_status, wallet_deposit.admin_notes AS wallet_deposit_admin_notes, wallet_deposit.processed_by AS wallet_deposit_processed_by, wallet_deposit.processed_at AS wallet_deposit_processed_at, wallet_deposit.created_at AS wallet_deposit_created_at 
FROM wallet_deposit 
WHERE wallet_deposit.user_id = ? ORDER BY wallet_deposit.created_at DESC
 LIMIT ? OFFSET ?]
[parameters: (1, 5, 0)]
(Background on this error at: https://sqlalche.me/e/20/e3q8)

Traceback (most recent call last)
File "/home/runner/workspace/.pythonlibs/lib/python3.11/site-packages/sqlalchemy/engine/base.py", line 1963, in _exec_single_context
self.dialect.do_execute(
^
File "/home/runner/workspace/.pythonlibs/lib/python3.11/site-packages/sqlalchemy/engine/default.py", line 943, in do_execute
cursor.execute(statement, parameters)
^^^^^^^^^^^^^^^^^^^^^^^^^^^^^^^^^^^^^
The above exception was the direct cause of the following exception:
File "/home/runner/workspace/.pythonlibs/lib/python3.11/site-packages/flask/app.py", line 1536, in __call__
return self.wsgi_app(environ, start_response)
       ^^^^^^^^^^^^^^^^^^^^^^^^^^^^^^^^^^^^^^
File "/home/runner/workspace/.pythonlibs/lib/python3.11/site-packages/flask/app.py", line 1514, in wsgi_app
response = self.handle_exception(e)
           ^^^^^^^^^^^^^^^^^^^^^^^^
File "/home/runner/workspace/.pythonlibs/lib/python3.11/site-packages/flask_cors/extension.py", line 176, in wrapped_function
return cors_after_request(app.make_response(f(*args, **kwargs)))
                                            ^^^^^^^^^^^^^^^^^^
File "/home/runner/workspace/.pythonlibs/lib/python3.11/site-packages/flask/app.py", line 1511, in wsgi_app
response = self.full_dispatch_request()
           ^^^^^^^^^^^^^^^^^^^^^^^^^^^^
File "/home/runner/workspace/.pythonlibs/lib/python3.11/site-packages/flask/app.py", line 919, in full_dispatch_request
rv = self.handle_user_exception(e)
     ^^^^^^^^^^^^^^^^^^^^^^^^^^^^^
File "/home/runner/workspace/.pythonlibs/lib/python3.11/site-packages/flask_cors/extension.py", line 176, in wrapped_function
return cors_after_request(app.make_response(f(*args, **kwargs)))
                                            ^^^^^^^^^^^^^^^^^^
File "/home/runner/workspace/.pythonlibs/lib/python3.11/site-packages/flask/app.py", line 917, in full_dispatch_request
rv = self.dispatch_request()
     ^^^^^^^^^^^^^^^^^^^^^^^
File "/home/runner/workspace/.pythonlibs/lib/python3.11/site-packages/flask/app.py", line 902, in dispatch_request
return self.ensure_sync(self.view_functions[rule.endpoint])(**view_args)  # type: ignore[no-any-return]
       ^^^^^^^^^^^^^^^^^^^^^^^^^^^^^^^^^^^^^^^^^^^^^^^^^^^^^^^^^^^^^^^^^
File "/home/runner/workspace/.pythonlibs/lib/python3.11/site-packages/flask_login/utils.py", line 290, in decorated_view
return current_app.ensure_sync(func)(*args, **kwargs)
       ^^^^^^^^^^^^^^^^^^^^^^^^^^^^^^^^^^^^^^^^^^^^^^
File "/home/runner/workspace/app.py", line 224, in dashboard
user_deposits = WalletDeposit.query.filter_by(user_id=current_user.id).order_by(WalletDeposit.created_at.desc()).limit(5).all()
                ^^^^^^^^^^^^^^^^^^^^^^^^^^^^^^^^^^^^^^^^^^^^^^^^^^^^^^^^^^^^^^^^^^^^^^^^^^^^^^^^^^^^^^^^^^^^^^^^^^^^^^^^^^^^^^^
File "/home/runner/workspace/.pythonlibs/lib/python3.11/site-packages/sqlalchemy/orm/query.py", line 2704, in all
return self._iter().all()  # type: ignore
       ^^^^^^^^^^^^
File "/home/runner/workspace/.pythonlibs/lib/python3.11/site-packages/sqlalchemy/orm/query.py", line 2857, in _iter
result: Union[ScalarResult[_T], Result[_T]] = self.session.execute(
                                              
File "/home/runner/workspace/.pythonlibs/lib/python3.11/site-packages/sqlalchemy/orm/session.py", line 2365, in execute
return self._execute_internal(
       
File "/home/runner/workspace/.pythonlibs/lib/python3.11/site-packages/sqlalchemy/orm/session.py", line 2251, in _execute_internal
result: Result[Any] = compile_state_cls.orm_execute_statement(
                      
File "/home/runner/workspace/.pythonlibs/lib/python3.11/site-packages/sqlalchemy/orm/context.py", line 306, in orm_execute_statement
result = conn.execute(
         
File "/home/runner/workspace/.pythonlibs/lib/python3.11/site-packages/sqlalchemy/engine/base.py", line 1415, in execute
return meth(
       
File "/home/runner/workspace/.pythonlibs/lib/python3.11/site-packages/sqlalchemy/sql/elements.py", line 523, in _execute_on_connection
return connection._execute_clauseelement(
       
File "/home/runner/workspace/.pythonlibs/lib/python3.11/site-packages/sqlalchemy/engine/base.py", line 1637, in _execute_clauseelement
ret = self._execute_context(
      
File "/home/runner/workspace/.pythonlibs/lib/python3.11/site-packages/sqlalchemy/engine/base.py", line 1842, in _execute_context
return self._exec_single_context(
       
File "/home/runner/workspace/.pythonlibs/lib/python3.11/site-packages/sqlalchemy/engine/base.py", line 1982, in _exec_single_context
self._handle_dbapi_exception(
^
File "/home/runner/workspace/.pythonlibs/lib/python3.11/site-packages/sqlalchemy/engine/base.py", line 2351, in _handle_dbapi_exception
raise sqlalchemy_exception.with_traceback(exc_info[2]) from e
^^^^^^^^^^^^^^^^^^^^^^^^^^^^^^^^^^^^^^^^^^^^^^^^^^^^^^^^^^^^^
File "/home/runner/workspace/.pythonlibs/lib/python3.11/site-packages/sqlalchemy/engine/base.py", line 1963, in _exec_single_context
self.dialect.do_execute(
^
File "/home/runner/workspace/.pythonlibs/lib/python3.11/site-packages/sqlalchemy/engine/default.py", line 943, in do_execute
cursor.execute(statement, parameters)
^^^^^^^^^^^^^^^^^^^^^^^^^^^^^^^^^^^^^
sqlalchemy.exc.OperationalError: (sqlite3.OperationalError) no such column: wallet_deposit.deposit_method
[SQL: SELECT wallet_deposit.id AS wallet_deposit_id, wallet_deposit.user_id AS wallet_deposit_user_id, wallet_deposit.amount AS wallet_deposit_amount, wallet_deposit.deposit_method AS wallet_deposit_deposit_method, wallet_deposit.bank_name AS wallet_deposit_bank_name, wallet_deposit.account_number AS wallet_deposit_account_number, wallet_deposit.account_name AS wallet_deposit_account_name, wallet_deposit.payment_proof AS wallet_deposit_payment_proof, wallet_deposit.reference_number AS wallet_deposit_reference_number, wallet_deposit.status AS wallet_deposit_status, wallet_deposit.admin_notes AS wallet_deposit_admin_notes, wallet_deposit.processed_by AS wallet_deposit_processed_by, wallet_deposit.processed_at AS wallet_deposit_processed_at, wallet_deposit.created_at AS wallet_deposit_created_at
FROM wallet_deposit
WHERE wallet_deposit.user_id = ? ORDER BY wallet_deposit.created_at DESC
LIMIT ? OFFSET ?]
[parameters: (1, 5, 0)]
(Background on this error at: https://sqlalche.me/e/20/e3q8)
The debugger caught an exception in your WSGI application. You can now look at the traceback which led to the error.
To switch between the interactive traceback and the plaintext one, you can click on the "Traceback" headline. From the text traceback you can also create a paste of it.

Brought to you by DON'T PANIC, your friendly Werkzeug powered traceback interpreter.